Workbook
Name abc: #REF!

Sheet Sheet4
A1: CustomerName | B1: Branch | C1: Country | D1: TransactionType | E1: Category | F1: Currency | G1: Amount | H1: AmountUSD | M1: number
A2: Aisha Singh | B2: London | C2: UK | D2: Withdrawal | E2: Dining | F2: EUR | G2: 955.8 | H2: 1032.264 | M2: 955.8 | N2: =4867*M2 -> 4651878.6 | O2: 4651878.6
A3: David Mueller | B3: Tokyo | C3: Japan | D3: Fee | E3: Other | F3: USD | G3: 12.41 | H3: 12.41 | M3: 12.41 | N3: =4867*M3 -> 60399.47 | O3: 60399.47
A4: Mohammed Sato | B4: Toronto | C4: Canada | D4: Withdrawal | E4: Dining | F4: USD | G4: 1842.59 | H4: 1842.59 | M4: 1842.59 | N4: =4867*M4 -> 8967885.5 | O4: 8967885.5
A5: Richard Harris | B5: New York | C5: USA | D5: Withdrawal | E5: Entertainment | F5: EUR | G5: 522.01 | H5: 563.7708 | M5: 522.01 | N5: =4867*M5 -> 2540622.7 | O5: 2540622.7
A6: Susan Miller | B6: New York | C6: USA | D6: Withdrawal | E6: Shopping | F6: USD | G6: 874.91 | H6: 874.91 | M6: 874.91 | N6: =4867*M6 -> 4258187 | O6: 4258187
A7: Kenji Sato | B7: Sydney | C7: Australia | D7: Payment | E7: Education | F7: USD | G7: 4131.94 | H7: 4131.94 | M7: 4131.94 | N7: =4867*M7 -> 20110152 | O7: 20110152
A8: Joseph Wilson | B8: Singapore | C8: Singapore | D8: Deposit | E8: Salary | F8: CNY | G8: 10999.85 | H8: 1539.979 | M8: 10999.85 | N8: =4867*M8 -> 53536270 | O8: 53536270
A9: Charles Park | B9: New York | C9: USA | D9: Deposit | E9: Salary | F9: CNY | G9: 4276.34 | H9: 598.6876 | M9: 4276.34 | N9: =4867*M9 -> 20812947 | O9: 20812947
A10: David Wilson | B10: Toronto | C10: Canada | D10: Payment | E10: Shopping | F10: USD | G10: 836 | H10: 836 | M10: 836 | N10: =4867*M10 -> 4068812 | O10: 4068812
A11: Michael Lopez | B11: Toronto | C11: Canada | D11: Fee | E11: Other | F11: USD | G11: 24.12 | H11: 24.12 | M11: 24.12 | N11: =4867*M11 -> 117392.04 | O11: 117392.04
A12: Deepa Mueller | B12: Singapore | C12: Singapore | D12: Withdrawal | E12: Dining | F12: USD | G12: 1514.19 | H12: 1514.19 | M12: 1514.19 | N12: =4867*M12 -> 7369562.7 | O12: 7369562.7
A13: Li Brown | B13: Frankfurt | C13: Germany | D13: Transfer | E13: Other | F13: USD | G13: 1113.46 | H13: 1113.46 | M13: 1113.46 | N13: =4867*M13 -> 5419209.8 | O13: 5419209.8
... A21: Li Martin | B21: Hong Kong | C21: China | D21: Deposit | E21: Salary | F21: USD | G21: 3931.9 | H21: 3931.9 | M21: 3931.9 | N21: =4867*M21 -> 19136557 | O21: 19136557
H22: 1100
H23: 600

Sheet Sheet1
A1: CustomerName | B1: Branch | C1: Country | D1: TransactionType | E1: Category | F1: Currency | G1: Amount | H1: AmountUSD | I1: TransactionDate
A2: Aisha Singh | B2: London | C2: UK | D2: Withdrawal | E2: Dining | F2: EUR | G2: 955.8 | H2: =G2*VLOOKUP(F2,{"USD",1;"EUR",1.08;"GBP",1.27;"JPY",0.0067;"CNY",0.14;"INR",0.012},2,FALSE) -> 1032.264 | I2: 44774 | J2: 44774
A3: David Mueller | B3: Tokyo | C3: Japan | D3: Fee | E3: Other | F3: USD | G3: 12.41 | H3: =G3*VLOOKUP(F3,{"USD",1;"EUR",1.08;"GBP",1.27;"JPY",0.0067;"CNY",0.14;"INR",0.012},2,FALSE) -> 12.41 | I3: 2022-07-14 | J3: 44774
A4: Mohammed Sato | B4: Toronto | C4: Canada | D4: Withdrawal | E4: Dining | F4: USD | G4: 1842.59 | H4: =G4*VLOOKUP(F4,{"USD",1;"EUR",1.08;"GBP",1.27;"JPY",0.0067;"CNY",0.14;"INR",0.012},2,FALSE) -> 1842.59 | I4: 2024-01-23 | J4: 44774
A5: Richard Harris | B5: New York | C5: USA | D5: Withdrawal | E5: Entertainment | F5: EUR | G5: 522.01 | H5: =G5*VLOOKUP(F5,{"USD",1;"EUR",1.08;"GBP",1.27;"JPY",0.0067;"CNY",0.14;"INR",0.012},2,FALSE) -> 563.7708 | I5: 2023-06-17 | J5: 44774
A6: Susan Miller | B6: New York | C6: USA | D6: Withdrawal | E6: Shopping | F6: USD | G6: 874.91 | H6: =G6*VLOOKUP(F6,{"USD",1;"EUR",1.08;"GBP",1.27;"JPY",0.0067;"CNY",0.14;"INR",0.012},2,FALSE) -> 874.91 | I6: 2024-03-30 | J6: 44774
A7: Kenji Sato | B7: Sydney | C7: Australia | D7: Payment | E7: Education | F7: USD | G7: 4131.94 | H7: =G7*VLOOKUP(F7,{"USD",1;"EUR",1.08;"GBP",1.27;"JPY",0.0067;"CNY",0.14;"INR",0.012},2,FALSE) -> 4131.94 | I7: 2024-07-25 | J7: 44774
A8: Joseph Wilson | B8: Singapore | C8: Singapore | D8: Deposit | E8: Salary | F8: CNY | G8: 10999.85 | H8: =G8*VLOOKUP(F8,{"USD",1;"EUR",1.08;"GBP",1.27;"JPY",0.0067;"CNY",0.14;"INR",0.012},2,FALSE) -> 1539.979 | I8: 2025-07-02 | J8: 44774 | L8: 46189
A9: Charles Park | B9: New York | C9: USA | D9: Deposit | E9: Salary | F9: CNY | G9: 4276.34 | H9: =G9*VLOOKUP(F9,{"USD",1;"EUR",1.08;"GBP",1.27;"JPY",0.0067;"CNY",0.14;"INR",0.012},2,FALSE) -> 598.6876 | I9: 2025-09-25 | J9: 44774
A10: David Wilson | B10: Toronto | C10: Canada | D10: Payment | E10: Shopping | F10: USD | G10: 836 | H10: =G10*VLOOKUP(F10,{"USD",1;"EUR",1.08;"GBP",1.27;"JPY",0.0067;"CNY",0.14;"INR",0.012},2,FALSE) -> 836 | I10: 2022-05-22 | J10: 44774 | L10: 0.40833333
A11: Michael Lopez | B11: Toronto | C11: Canada | D11: Fee | E11: Other | F11: USD | G11: 24.12 | H11: =G11*VLOOKUP(F11,{"USD",1;"EUR",1.08;"GBP",1.27;"JPY",0.0067;"CNY",0.14;"INR",0.012},2,FALSE) -> 24.12 | I11: 2024-11-29 | J11: 44774
A12: Deepa Mueller | B12: Singapore | C12: Singapore | D12: Withdrawal | E12: Dining | F12: USD | G12: 1514.19 | H12: =G12*VLOOKUP(F12,{"USD",1;"EUR",1.08;"GBP",1.27;"JPY",0.0067;"CNY",0.14;"INR",0.012},2,FALSE) -> 1514.19 | I12: 2025-12-30 | J12: 44774
A13: Li Brown | B13: Frankfurt | C13: Germany | D13: Transfer | E13: Other | F13: USD | G13: 1113.46 | H13: =G13*VLOOKUP(F13,{"USD",1;"EUR",1.08;"GBP",1.27;"JPY",0.0067;"CNY",0.14;"INR",0.012},2,FALSE) -> 1113.46 | I13: 2024-10-17 | J13: 44774
A14: Raj Liu | B14: Sydney | C14: Australia | D14: Deposit | E14: Investment | F14: CNY | G14: 6320.1 | H14: =G14*VLOOKUP(F14,{"USD",1;"EUR",1.08;"GBP",1.27;"JPY",0.0067;"CNY",0.14;"INR",0.012},2,FALSE) -> 884.814 | I14: 2025-11-22 | J14: 44774
A15: Priya Thomas | B15: Frankfurt | C15: Germany | D15: Transfer | E15: Other | F15: USD | G15: 1597.27 | H15: =G15*VLOOKUP(F15,{"USD",1;"EUR",1.08;"GBP",1.27;"JPY",0.0067;"CNY",0.14;"INR",0.012},2,FALSE) -> 1597.27 | I15: 2024-08-11
A16: Anil Gonzalez | B16: London | C16: UK | D16: Loan | E16: Other | F16: USD | G16: 802.33 | H16: =G16*VLOOKUP(F16,{"USD",1;"EUR",1.08;"GBP",1.27;"JPY",0.0067;"CNY",0.14;"INR",0.012},2,FALSE) -> 802.33 | I16: 2025-07-14 | J16: =G16*G10/G11 -> 27808.784
A17: Charles Rodriguez | B17: Dubai | C17: UAE | D17: Payment | E17: Other | F17: USD | G17: 911.22 | H17: =G17*VLOOKUP(F17,{"USD",1;"EUR",1.08;"GBP",1.27;"JPY",0.0067;"CNY",0.14;"INR",0.012},2,FALSE) -> 911.22 | I17: 2024-02-19
A18: Kenji Sharma | B18: Singapore | C18: Singapore | D18: Transfer | E18: Other | F18: USD | G18: 2581.61 | H18: =G18*VLOOKUP(F18,{"USD",1;"EUR",1.08;"GBP",1.27;"JPY",0.0067;"CNY",0.14;"INR",0.012},2,FALSE) -> 2581.61 | I18: 2023-09-18
A19: Michael Jones | B19: Mumbai | C19: India | D19: Payment | E19: Other | F19: USD | G19: 3732.24 | H19: =G19*VLOOKUP(F19,{"USD",1;"EUR",1.08;"GBP",1.27;"JPY",0.0067;"CNY",0.14;"INR",0.012},2,FALSE) -> 3732.24 | I19: 2024-01-12
A20: Aisha Ahmed | B20: Hong Kong | C20: China | D20: Withdrawal | E20: Entertainment | F20: GBP | G20: 385.87 | H20: =G20*VLOOKUP(F20,{"USD",1;"EUR",1.08;"GBP",1.27;"JPY",0.0067;"CNY",0.14;"INR",0.012},2,FALSE) -> 490.0549 | I20: 2025-10-26
A21: Li Martin | B21: Hong Kong | C21: China | D21: Deposit | E21: Salary | F21: USD | G21: 3931.9 | H21: =G21*VLOOKUP(F21,{"USD",1;"EUR",1.08;"GBP",1.27;"JPY",0.0067;"CNY",0.14;"INR",0.012},2,FALSE) -> 3931.9 | I21: 2023-01-14
G22: =SUM(G2:G21) -> 47366.16

Sheet city-1
A1: Country | B1: Amount | C1: AmountUSD
A2: UK | B2: 955.8 | C2: 1032.264
A3: Japan | B3: 12.41 | C3: 100
A4: Canada | B4: 1842.59 | C4: 1842.59
A5: USA | B5: 522.01 | C5: 563.7708
A6: USA | B6: 874.91 | C6: 874.91
A7: Australia | B7: 4131.94 | C7: 4131.94
A8: Singapore | B8: 10999.85 | C8: 1539.979
A9: USA | B9: 4276.34 | C9: 598.6876
A10: Canada | B10: 836 | C10: 836

Sheet city-2
A1: Country | B1: Amount | C1: AmountUSD
A2: UK | B2: 955.8 | C2: 1032.264
A3: Japan | B3: 12.41 | C3: 12.41
A4: Canada | B4: 1842.59 | C4: 1842.59
A5: USA | B5: 522.01 | C5: 563.7708
A6: USA | B6: 874.91 | C6: 874.91
A7: Australia | B7: 4131.94 | C7: 4131.94
A8: Singapore | B8: 10999.85 | C8: 1539.979
A9: USA | B9: 4276.34 | C9: 598.6876
A10: Canada | B10: 836 | C10: 836

Sheet city-3
A1: Country | B1: Amount | C1: AmountUSD
A2: UK | B2: 955.8 | C2: 1032.264
A3: Japan | B3: 12.41 | C3: 12.41
A4: Canada | B4: 1842.59 | C4: 1842.59
A5: USA | B5: 522.01 | C5: 563.7708
A6: USA | B6: 874.91 | C6: 874.91
A7: Australia | B7: 4131.94 | C7: 4131.94
A8: Singapore | B8: 10999.85 | C8: 1539.979
A9: USA | B9: 4276.34 | C9: 598.6876
A10: Canada | B10: 836 | C10: 836

Sheet city-4
D6: Country | E6: Amount | F6: AmountUSD
D7: UK | E7: 955.8 | F7: 1032.264
D8: Japan | E8: 12.41 | F8: 12.41
D9: Canada | E9: 1842.59 | F9: 1842.59
D10: USA | E10: 522.01 | F10: 563.7708
D11: USA | E11: 874.91 | F11: 874.91
D12: Australia | E12: 4131.94 | F12: 4131.94
D13: Singapore | E13: 10999.85 | F13: 1539.979
D14: USA | E14: 4276.34 | F14: 598.6876
D15: Canada | E15: 836 | F15: 836

Sheet Sheet7
A1: Country | B1: Amount | C1: AmountUSD | I1: Country | J1: Amount | K1: AmountUSD
A2: UK | B2: =SUM('city-1'!B2,'city-2'!B2,'city-3'!B2) -> 2867.4 | C2: =SUM('city-1'!C2,'city-2'!C2,'city-3'!C2) -> 3096.792 | I2: UK | J2: =SUM('city-1'!B2,'city-2'!B2,'city-3'!B2,'city-4'!E7) -> 3823.2 | K2: =SUM('city-1'!C2,'city-2'!C2,'city-3'!C2,'city-4'!F7) -> 4129.056
A3: Japan | B3: =SUM('city-1'!B3,'city-2'!B3,'city-3'!B3) -> 37.23 | C3: =SUM('city-1'!C3,'city-2'!C3,'city-3'!C3) -> 124.82 | I3: Japan | J3: =SUM('city-1'!B3,'city-2'!B3,'city-3'!B3,'city-4'!E8) -> 49.64 | K3: =SUM('city-1'!C3,'city-2'!C3,'city-3'!C3,'city-4'!F8) -> 137.23
A4: Canada | B4: =SUM('city-1'!B4,'city-2'!B4,'city-3'!B4) -> 5527.77 | C4: =SUM('city-1'!C4,'city-2'!C4,'city-3'!C4) -> 5527.77 | I4: Canada | J4: =SUM('city-1'!B4,'city-2'!B4,'city-3'!B4,'city-4'!E9) -> 7370.36 | K4: =SUM('city-1'!C4,'city-2'!C4,'city-3'!C4,'city-4'!F9) -> 7370.36
A5: USA | B5: =SUM('city-1'!B5,'city-2'!B5,'city-3'!B5) -> 1566.03 | C5: =SUM('city-1'!C5,'city-2'!C5,'city-3'!C5) -> 1691.3124 | I5: USA | J5: =SUM('city-1'!B5,'city-2'!B5,'city-3'!B5,'city-4'!E10) -> 2088.04 | K5: =SUM('city-1'!C5,'city-2'!C5,'city-3'!C5,'city-4'!F10) -> 2255.0832
A6: USA | B6: =SUM('city-1'!B6,'city-2'!B6,'city-3'!B6) -> 2624.73 | C6: =SUM('city-1'!C6,'city-2'!C6,'city-3'!C6) -> 2624.73 | I6: USA | J6: =SUM('city-1'!B6,'city-2'!B6,'city-3'!B6,'city-4'!E11) -> 3499.64 | K6: =SUM('city-1'!C6,'city-2'!C6,'city-3'!C6,'city-4'!F11) -> 3499.64
A7: Australia | B7: =SUM('city-1'!B7,'city-2'!B7,'city-3'!B7) -> 12395.82 | C7: =SUM('city-1'!C7,'city-2'!C7,'city-3'!C7) -> 12395.82 | I7: Australia | J7: =SUM('city-1'!B7,'city-2'!B7,'city-3'!B7,'city-4'!E12) -> 16527.76 | K7: =SUM('city-1'!C7,'city-2'!C7,'city-3'!C7,'city-4'!F12) -> 16527.76
A8: Singapore | B8: =SUM('city-1'!B8,'city-2'!B8,'city-3'!B8) -> 32999.55 | C8: =SUM('city-1'!C8,'city-2'!C8,'city-3'!C8) -> 4619.937 | I8: Singapore | J8: =SUM('city-1'!B8,'city-2'!B8,'city-3'!B8,'city-4'!E13) -> 43999.4 | K8: =SUM('city-1'!C8,'city-2'!C8,'city-3'!C8,'city-4'!F13) -> 6159.916
A9: USA | B9: =SUM('city-1'!B9,'city-2'!B9,'city-3'!B9) -> 12829.02 | C9: =SUM('city-1'!C9,'city-2'!C9,'city-3'!C9) -> 1796.0628 | I9: USA | J9: =SUM('city-1'!B9,'city-2'!B9,'city-3'!B9,'city-4'!E14) -> 17105.36 | K9: =SUM('city-1'!C9,'city-2'!C9,'city-3'!C9,'city-4'!F14) -> 2394.7504
A10: Canada | B10: =SUM('city-1'!B10,'city-2'!B10,'city-3'!B10) -> 2508 | C10: =SUM('city-1'!C10,'city-2'!C10,'city-3'!C10) -> 2508 | I10: Canada | J10: =SUM('city-1'!B10,'city-2'!B10,'city-3'!B10,'city-4'!E15) -> 3344 | K10: =SUM('city-1'!C10,'city-2'!C10,'city-3'!C10,'city-4'!F15) -> 3344

Sheet Sheet9
C1: Amount | D1: AmountUSD
B2: Book1 | C2: ='city-1'!$B$2 -> 955.8 | D2: ='city-1'!$C$2 -> 1032.264
B3: Book1 | C3: ='city-2'!$B$2 -> 955.8 | D3: ='city-2'!$C$2 -> 1032.264
B4: Book1 | C4: ='city-3'!$B$2 -> 955.8 | D4: ='city-3'!$C$2 -> 1032.264
B5: Book1 | C5: ='city-4'!$E$7 -> 955.8 | D5: ='city-4'!$F$7 -> 1032.264
A6: UK | C6: =SUM(C2:C5) -> 3823.2 | D6: =SUM(D2:D5) -> 4129.056
B7: Book1 | C7: ='city-1'!$B$3 -> 12.41 | D7: ='city-1'!$C$3 -> 100
B8: Book1 | C8: ='city-2'!$B$3 -> 12.41 | D8: ='city-2'!$C$3 -> 12.41
B9: Book1 | C9: ='city-3'!$B$3 -> 12.41 | D9: ='city-3'!$C$3 -> 12.41
B10: Book1 | C10: ='city-4'!$E$8 -> 12.41 | D10: ='city-4'!$F$8 -> 12.41
A11: Japan | C11: =SUM(C7:C10) -> 49.64 | D11: =SUM(D7:D10) -> 137.23 | H11: =Sheet1!L8 -> 46189
B12: Book1 | C12: ='city-1'!$B$4 -> 1842.59 | D12: ='city-1'!$C$4 -> 1842.59
C13: ='city-1'!$B$10 -> 836 | D13: ='city-1'!$C$10 -> 836
B14: Book1 | C14: ='city-2'!$B$4 -> 1842.59 | D14: ='city-2'!$C$4 -> 1842.59
C15: ='city-2'!$B$10 -> 836 | D15: ='city-2'!$C$10 -> 836
B16: Book1 | C16: ='city-3'!$B$4 -> 1842.59 | D16: ='city-3'!$C$4 -> 1842.59
C17: ='city-3'!$B$10 -> 836 | D17: ='city-3'!$C$10 -> 836
B18: Book1 | C18: ='city-4'!$E$9 -> 1842.59 | D18: ='city-4'!$F$9 -> 1842.59
C19: ='city-4'!$E$15 -> 836 | D19: ='city-4'!$F$15 -> 836
A20: Canada | C20: =SUM(C12:C19) -> 10714.36 | D20: =SUM(D12:D19) -> 10714.36
B21: Book1 | C21: ='city-1'!$B$5 -> 522.01 | D21: ='city-1'!$C$5 -> 563.7708
C22: ='city-1'!$B$6 -> 874.91 | D22: ='city-1'!$C$6 -> 874.91
C23: ='city-1'!$B$9 -> 4276.34 | D23: ='city-1'!$C$9 -> 598.6876
B24: Book1 | C24: ='city-2'!$B$5 -> 522.01 | D24: ='city-2'!$C$5 -> 563.7708
C25: ='city-2'!$B$6 -> 874.91 | D25: ='city-2'!$C$6 -> 874.91
C26: ='city-2'!$B$9 -> 4276.34 | D26: ='city-2'!$C$9 -> 598.6876
B27: Book1 | C27: ='city-3'!$B$5 -> 522.01 | D27: ='city-3'!$C$5 -> 563.7708
C28: ='city-3'!$B$6 -> 874.91 | D28: ='city-3'!$C$6 -> 874.91
C29: ='city-3'!$B$9 -> 4276.34 | D29: ='city-3'!$C$9 -> 598.6876
B30: Book1 | C30: ='city-4'!$E$10 -> 522.01 | D30: ='city-4'!$F$10 -> 563.7708
C31: ='city-4'!$E$11 -> 874.91 | D31: ='city-4'!$F$11 -> 874.91
C32: ='city-4'!$E$14 -> 4276.34 | D32: ='city-4'!$F$14 -> 598.6876
A33: USA | C33: =SUM(C21:C32) -> 22693.04 | D33: =SUM(D21:D32) -> 8149.4736
B34: Book1 | C34: ='city-1'!$B$7 -> 4131.94 | D34: ='city-1'!$C$7 -> 4131.94
B35: Book1 | C35: ='city-2'!$B$7 -> 4131.94 | D35: ='city-2'!$C$7 -> 4131.94
B36: Book1 | C36: ='city-3'!$B$7 -> 4131.94 | D36: ='city-3'!$C$7 -> 4131.94
B37: Book1 | C37: ='city-4'!$E$12 -> 4131.94 | D37: ='city-4'!$F$12 -> 4131.94
A38: Australia | C38: =SUM(C34:C37) -> 16527.76 | D38: =SUM(D34:D37) -> 16527.76
B39: Book1 | C39: ='city-1'!$B$8 -> 10999.85 | D39: ='city-1'!$C$8 -> 1539.979
B40: Book1 | C40: ='city-2'!$B$8 -> 10999.85 | D40: ='city-2'!$C$8 -> 1539.979
...

Sheet Sheet10
A1: CustomerName | B1: Branch | C1: Country | D1: TransactionType | E1: Category | F1: Currency | G1: Amount | H1: AmountUSD
A2: Aisha Singh | B2: London | C2: UK | D2: Withdrawal | E2: Dining | F2: EUR | G2: 955.8 | H2: 1032.264
A3: David Mueller | B3: Tokyo | C3: Japan | D3: Fee | E3: Other | F3: USD | G3: 12.41 | H3: 12.41
A4: Mohammed Sato | B4: Toronto | C4: Canada | D4: Withdrawal | E4: Dining | F4: USD | G4: 1842.59 | H4: 1842.59
A5: Richard Harris | B5: New York | C5: USA | D5: Withdrawal | E5: Entertainment | F5: EUR | G5: 522.01 | H5: 563.7708
A6: Susan Miller | B6: New York | C6: USA | D6: Withdrawal | E6: Shopping | F6: USD | G6: 874.91 | H6: 874.91
A7: Kenji Sato | B7: Sydney | C7: Australia | D7: Payment | E7: Education | F7: USD | G7: 4131.94 | H7: 4131.94
A8: Joseph Wilson | B8: Singapore | C8: Singapore | D8: Deposit | E8: Salary | F8: CNY | G8: 10999.85 | H8: 1539.979
A9: Charles Park | B9: New York | C9: USA | D9: Deposit | E9: Salary | F9: CNY | G9: 4276.34 | H9: 598.6876
A10: David Wilson | B10: Toronto | C10: Canada | D10: Payment | E10: Shopping | F10: USD | G10: 836 | H10: 836
A11: Michael Lopez | B11: Toronto | C11: Canada | D11: Fee | E11: Other | F11: USD | G11: 24.12 | H11: 24.12
A12: Deepa Mueller | B12: Singapore | C12: Singapore | D12: Withdrawal | E12: Dining | F12: USD | G12: 1514.19 | H12: 1514.19
A13: Li Brown | B13: Frankfurt | C13: Germany | D13: Transfer | E13: Other | F13: USD | G13: 1113.46 | H13: 1113.46
... A21: Li Martin | B21: Hong Kong | C21: China | D21: Deposit | E21: Salary | F21: USD | G21: 3931.9 | H21: 3931.9

Sheet Sheet11
A1: CustomerName | B1: Branch | C1: Country | D1: TransactionType | E1: Category | F1: Currency | G1: Amount | H1: AmountUSD | I1: Date | M1: Currency
A2: Aisha Singh | B2: London | C2: UK | D2: Withdrawal | E2: Dining | F2: EUR | G2: 955.8 | H2: 1032.264 | I2: 44756 | M2: USD
A3: David Mueller | B3: Tokyo | C3: Japan | D3: Fee | E3: Other | F3: USD | G3: 12.41 | H3: 12.41 | I3: 44756 | K3: 2022-17-4 | M3: CNY
A4: Mohammed Sato | B4: Toronto | C4: Canada | D4: Withdrawal | E4: Dining | F4: USD | G4: 1842.59 | H4: 1842.59 | I4: 45314 | K4: 2024-21-03 | M4: EUR
A5: Richard Harris | B5: New York | C5: USA | D5: Withdrawal | E5: Entertainment | F5: EUR | G5: 522.01 | H5: 563.7708 | I5: 45094 | K5: 2023-06-17
A6: Susan Miller | B6: New York | C6: USA | D6: Withdrawal | E6: Shopping | F6: USD | G6: 874.91 | H6: 874.91 | I6: 45381 | K6: 2024-03-30 | M6: USD
A7: Kenji Sato | B7: Sydney | C7: Australia | D7: Payment | E7: Education | F7: USD | G7: 4131.94 | H7: 4131.94 | I7: 45498 | K7: 07-25-2014
A8: Joseph Wilson | B8: Singapore | C8: Singapore | D8: Deposit | E8: Salary | F8: CNY | G8: 10999.85 | H8: 1539.979 | I8: 45840 | K8: 46159
A9: Charles Park | B9: New York | C9: USA | D9: Deposit | E9: Salary | F9: CNY | G9: 4276.34 | H9: 598.6876 | I9: 45925 | K9: 2025-09-25
A10: David Wilson | B10: Toronto | C10: Canada | D10: Payment | E10: Shopping | F10: USD | G10: 836 | H10: 836 | I10: 44703 | K10: 2022-05-22
A11: Michael Lopez | B11: Toronto | C11: Canada | D11: Fee | E11: Other | F11: USD | G11: 24.12 | H11: 24.12 | I11: 45625 | K11: 2024-11-29
A12: Deepa Mueller | B12: Singapore | C12: Singapore | D12: Withdrawal | E12: Dining | F12: USD | G12: 1514.19 | H12: 1514.19 | I12: 46021
A13: Li Brown | B13: Frankfurt | C13: Germany | D13: Transfer | E13: Other | F13: USD | G13: 1113.46 | H13: 1113.46 | I13: 45582
A14: Raj Liu | B14: Sydney | C14: Australia | D14: Deposit | E14: Investment | F14: CNY | G14: 6320.1 | H14: 884.814 | I14: 45983
A15: Priya Thomas | B15: Frankfurt | C15: Germany | D15: Transfer | E15: Other | F15: USD | G15: 1597.27 | H15: 1597.27 | I15: 45515
A16: Anil Gonzalez | B16: London | C16: UK | D16: Loan | E16: Other | F16: USD | G16: 802.33 | H16: 802.33 | I16: 45852
A17: Charles Rodriguez | B17: Dubai | C17: UAE | D17: Payment | E17: Other | F17: USD | G17: 911.22 | H17: 911.22 | I17: 45341
A18: Kenji Sharma | B18: Singapore | C18: Singapore | D18: Transfer | E18: Other | F18: USD | G18: 2581.61 | H18: 2581.61 | I18: 45187
A19: Michael Jones | B19: Mumbai | C19: India | D19: Payment | E19: Other | F19: USD | G19: 3732.24 | H19: 3732.24 | I19: 45303
A20: Aisha Ahmed | B20: Hong Kong | C20: China | D20: Withdrawal | E20: Entertainment | F20: GBP | G20: 385.87 | H20: 490.0549 | I20: 45956
A21: Li Martin | B21: Hong Kong | C21: China | D21: Deposit | E21: Salary | F21: USD | G21: 3931.9 | H21: 3931.9 | I21: 44940
E26: {=_xlfn.UNIQUE(F2:F21)} -> EUR | G26: {=_xlfn.UNIQUE(C2:C21)} -> UK
E27: USD | G27: Japan
E28: CNY | G28: Canada
E29: GBP | G29: USA
G30: Australia
G31: Singapore
G32: Germany
G33: UAE
G34: India
G35: China

Sheet Data
A1: CustomerName | B1: Branch | C1: Country | D1: TransactionType | E1: Category | F1: Currency | G1: Amount
A2: Aisha Singh | B2: London | C2: UK | D2: Withdrawal | E2: Dining | F2: EUR | G2: 955.8
A3: David Mueller | B3: Tokyo | C3: Japan | D3: Fee | E3: Other | F3: USD | G3: 12.41
A4: Mohammed Sato | B4: Toronto | C4: Canada | D4: Withdrawal | E4: Dining | F4: USD | G4: 1842.59
A5: Richard Harris | B5: New York | C5: USA | D5: Withdrawal | E5: Entertainment | F5: EUR | G5: 522.01
A6: Susan Miller | B6: New York | C6: USA | D6: Withdrawal | E6: Shopping | F6: USD | G6: 874.91
A7: Kenji Sato | B7: Sydney | C7: Australia | D7: Payment | E7: Education | F7: USD | G7: 4131.94
A8: Joseph Wilson | B8: Singapore | C8: Singapore | D8: Deposit | E8: Salary | F8: CNY | G8: 10999.85
A9: Charles Park | B9: New York | C9: USA | D9: Deposit | E9: Salary | F9: CNY | G9: 4276.34
A10: Wei White | B10: Frankfurt | C10: Germany | D10: Payment | E10: Insurance | F10: USD | G10: 3986.97
A11: David Wilson | B11: Toronto | C11: Canada | D11: Payment | E11: Shopping | F11: USD | G11: 836
A12: Michael Lopez | B12: Toronto | C12: Canada | D12: Fee | E12: Other | F12: USD | G12: 24.12
A13: Deepa Mueller | B13: Singapore | C13: Singapore | D13: Withdrawal | E13: Dining | F13: USD | G13: 1514.19
... A438: Luis Tran | B438: Hong Kong | C438: China | D438: Deposit | E438: Salary | F438: GBP | G438: 7874.84

Sheet Sheet12
A1: Country
A2: {=_xlfn.UNIQUE(Data!C2:C438)} -> UK
A3: Japan
A4: Canada | C4: INR
A5: USA
A6: Australia
A7: Singapore
A8: Germany
A9: UAE
A10: India
A11: China
B12: country
B13: China | D13: {=_xlfn._xlws.FILTER(Data!A2:G438,Data!C2:C438=Sheet12!B13)} -> Aisha Ahmed | E13: Hong Kong | F13: China | G13: Withdrawal | H13: Entertainment | I13: GBP | J13: 385.87 | M13: {=_xlfn._xlws.FILTER(Data!A2:G438,(Data!C2:C438=Sheet12!B13)*(Data!F2:F438="USD"))} -> Li Martin | N13: Hong Kong | O13: China | P13: Deposit | Q13: Salary | R13: USD | S13: 3931.9
D14: Li Martin | E14: Hong Kong | F14: China | G14: Deposit | H14: Salary | I14: USD | J14: 3931.9 | M14: Anil Khan | N14: Hong Kong | O14: China | P14: Withdrawal | Q14: Entertainment | R14: USD | S14: 1850.96
D15: Aisha Kumar | E15: Hong Kong | F15: China | G15: Fee | H15: Other | I15: EUR | J15: 19.21 | M15: Pierre Gonzalez | N15: Hong Kong | O15: China | P15: Investment | Q15: Investment | R15: USD | S15: 34866.89
D16: Linda Cohen | E16: Hong Kong | F16: China | G16: Transfer | H16: Other | I16: CNY | J16: 1965.55 | M16: John Sato | N16: Hong Kong | O16: China | P16: Deposit | Q16: Salary | R16: USD | S16: 7750.52
D17: Richard Singh | E17: Hong Kong | F17: China | G17: Fee | H17: Other | I17: EUR | J17: 46.18 | M17: Susan Sharma | N17: Hong Kong | O17: China | P17: Loan | Q17: Other | R17: USD | S17: 8022.55
D18: Elizabeth Moore | E18: Hong Kong | F18: China | G18: Transfer | H18: Other | I18: EUR | J18: 4589.84 | M18: John White | N18: Hong Kong | O18: China | P18: Payment | Q18: Utilities | R18: USD | S18: 1874.99
D19: Aisha Ahmed | E19: Hong Kong | F19: China | G19: Withdrawal | H19: Dining | I19: GBP | J19: 1650.58 | M19: Susan Chen | N19: Hong Kong | O19: China | P19: Deposit | Q19: Salary | R19: USD | S19: 11320.15
D20: Li Gonzalez | E20: Hong Kong | F20: China | G20: Withdrawal | H20: Transport | I20: GBP | J20: 1919.92 | M20: Linda Cohen | N20: Hong Kong | O20: China | P20: Withdrawal | Q20: Shopping | R20: USD | S20: 1434.73
D21: Aisha Ahmed | E21: Hong Kong | F21: China | G21: Transfer | H21: Other | I21: INR | J21: 9822.49 | M21: Ivan Wang | N21: Hong Kong | O21: China | P21: Deposit | Q21: Investment | R21: USD | S21: 9350.98
D22: Anil Khan | E22: Hong Kong | F22: China | G22: Withdrawal | H22: Entertainment | I22: USD | J22: 1850.96 | M22: Li Gonzalez | N22: Hong Kong | O22: China | P22: Payment | Q22: Healthcare | R22: USD | S22: 1671.25
D23: Pierre Gonzalez | E23: Hong Kong | F23: China | G23: Investment | H23: Investment | I23: USD | J23: 34866.89 | M23: Susan Sharma | N23: Hong Kong | O23: China | P23: Loan | Q23: Other | R23: USD | S23: 65726.24
D24: Priya Suzuki | E24: Hong Kong | F24: China | G24: Withdrawal | H24: Transport | I24: EUR | J24: 374.55 | M24: Linda Cohen | N24: Hong Kong | O24: China | P24: Fee | Q24: Other | R24: USD | S24: 15.73
D25: Pierre Levi | E25: Hong Kong | F25: China | G25: Transfer | H25: Other | I25: EUR | J25: 1931.85 | M25: Luis Tran | N25: Hong Kong | O25: China | P25: Withdrawal | Q25: Groceries | R25: USD | S25: 1315.39
... D41: John White | E41: Hong Kong | F41: China | G41: Deposit | H41: Investment | I41: USD | J41: 6845.42 | M41: Pierre Tanaka | N41: Hong Kong | O41: China | P41: Refund | Q41: Other | R41: USD | S41: 440.47
D42: Anil Khan | E42: Hong Kong | F42: China | G42: Payment | H42: Other | I42: EUR | J42: 4258.3
D43: Hans Tran | E43: Hong Kong | F43: China | G43: Withdrawal | H43: Other | I43: JPY | J43: 813.97
D44: John Sato | E44: Hong Kong | F44: China | G44: Investment | H44: Investment | I44: USD | J44: 31108.14
D45: Pierre Gonzalez | E45: Hong Kong | F45: China | G45: Withdrawal | H45: Dining | I45: JPY | J45: 118.71
D46: Li Gonzalez | E46: Hong Kong | F46: China | G46: Payment | H46: Insurance | I46: USD | J46: 132.31
D47: Mohammed Martinez | E47: Hong Kong | F47: China | G47: Withdrawal | H47: Dining | I47: EUR | J47: 1130.64
D48: Hans Tran | E48: Hong Kong | F48: China | G48: Payment | H48: Shopping | I48: JPY | J48: 4991.18
D49: Hans Tran | E49: Hong Kong | F49: China | G49: Deposit | H49: Investment | I49: USD | J49: 11585
D50: Hans Tran | E50: Hong Kong | F50: China | G50: Refund | H50: Dining | I50: USD | J50: 492.29
D51: Aisha Ahmed | E51: Hong Kong | F51: China | G51: Payment | H51: Rent | I51: USD | J51: 2351.92
D52: Li Martin | E52: Hong Kong | F52: China | G52: Withdrawal | H52: Entertainment | I52: USD | J52: 1090.8
D53: Aisha Kumar | E53: Hong Kong | F53: China | G53: Deposit | H53: Other | I53: USD | J53: 6309.9
... D67: Luis Tran | E67: Hong Kong | F67: China | G67: Deposit | H67: Salary | I67: GBP | J67: 7874.84
