Workbook

Sheet Sheet1
A1: TransactionID | B1: TransactionDate | C1: AccountID | D1: CustomerID | E1: CustomerName | F1: Branch | G1: Country | H1: TransactionType | I1: Category | J1: Currency | K1: Amount | L1: AmountUSD | M1: Balance
A2: TXN0000001 | B2: 2022-08-01 | C2: ACC100253 | D2: CUST10125 | E2: Aisha Singh | F2: London | G2: UK | H2: Withdrawal | I2: Dining | J2: EUR | K2: 955.8 | L2: =K2*VLOOKUP(J2,{"USD",1;"EUR",1.08;"GBP",1.27;"JPY",0.0067;"CNY",0.14;"INR",0.012},2,FALSE) -> 1032.264 | M2: 240457.01
A3: TXN0000002 | B3: 2022-07-14 | C3: ACC100275 | D3: CUST10137 | E3: David Mueller | F3: Tokyo | G3: Japan | H3: Fee | I3: Other | J3: USD | K3: 12.41 | L3: =K3*VLOOKUP(J3,{"USD",1;"EUR",1.08;"GBP",1.27;"JPY",0.0067;"CNY",0.14;"INR",0.012},2,FALSE) -> 12.41 | M3: 109657.63
A4: TXN0000003 | B4: 2024-01-23 | C4: ACC100012 | D4: CUST10006 | E4: Mohammed Sato | F4: Toronto | G4: Canada | H4: Withdrawal | I4: Dining | J4: USD | K4: 1842.59 | L4: =K4*VLOOKUP(J4,{"USD",1;"EUR",1.08;"GBP",1.27;"JPY",0.0067;"CNY",0.14;"INR",0.012},2,FALSE) -> 1842.59 | M4: 438961.01
A5: TXN0000004 | B5: 2023-06-17 | C5: ACC100307 | D5: CUST10152 | E5: Richard Harris | F5: New York | G5: USA | H5: Withdrawal | I5: Entertainment | J5: EUR | K5: 522.01 | L5: =K5*VLOOKUP(J5,{"USD",1;"EUR",1.08;"GBP",1.27;"JPY",0.0067;"CNY",0.14;"INR",0.012},2,FALSE) -> 563.7708 | M5: 245250.85
A6: TXN0000005 | B6: 2024-03-30 | C6: ACC100160 | D6: CUST10076 | E6: Susan Miller | F6: New York | G6: USA | H6: Withdrawal | I6: Shopping | J6: USD | K6: 874.91 | L6: =K6*VLOOKUP(J6,{"USD",1;"EUR",1.08;"GBP",1.27;"JPY",0.0067;"CNY",0.14;"INR",0.012},2,FALSE) -> 874.91 | M6: 412084.25
A7: TXN0000006 | B7: 2024-07-25 | C7: ACC100204 | D7: CUST10099 | E7: Kenji Sato | F7: Sydney | G7: Australia | H7: Payment | I7: Education | J7: USD | K7: 4131.94 | L7: =K7*VLOOKUP(J7,{"USD",1;"EUR",1.08;"GBP",1.27;"JPY",0.0067;"CNY",0.14;"INR",0.012},2,FALSE) -> 4131.94 | M7: 311006.01
A8: TXN0000007 | B8: 2025-07-02 | C8: ACC100094 | D8: CUST10045 | E8: Joseph Wilson | F8: Singapore | G8: Singapore | H8: Deposit | I8: Salary | J8: CNY | K8: 10999.85 | L8: =K8*VLOOKUP(J8,{"USD",1;"EUR",1.08;"GBP",1.27;"JPY",0.0067;"CNY",0.14;"INR",0.012},2,FALSE) -> 1539.979 | M8: 241947.91
A9: TXN0000008 | B9: 2025-09-25 | C9: ACC100367 | D9: CUST10178 | E9: Charles Park | F9: New York | G9: USA | H9: Deposit | I9: Salary | J9: CNY | K9: 4276.34 | L9: =K9*VLOOKUP(J9,{"USD",1;"EUR",1.08;"GBP",1.27;"JPY",0.0067;"CNY",0.14;"INR",0.012},2,FALSE) -> 598.6876 | M9: 53409.85
A10: TXN0000009 | B10: 2024-05-29 | C10: ACC100169 | D10: CUST10080 | E10: Wei White | F10: Frankfurt | G10: Germany | H10: Payment | I10: Insurance | J10: USD | K10: 3986.97 | L10: =K10*VLOOKUP(J10,{"USD",1;"EUR",1.08;"GBP",1.27;"JPY",0.0067;"CNY",0.14;"INR",0.012},2,FALSE) -> 3986.97 | M10: 365856.11
A11: TXN0000010 | B11: 2022-05-22 | C11: ACC100465 | D11: CUST10226 | E11: David Wilson | F11: Toronto | G11: Canada | H11: Payment | I11: Shopping | J11: USD | K11: 836 | L11: =K11*VLOOKUP(J11,{"USD",1;"EUR",1.08;"GBP",1.27;"JPY",0.0067;"CNY",0.14;"INR",0.012},2,FALSE) -> 836 | M11: 27106.88
A12: TXN0000011 | B12: 2024-11-29 | C12: ACC100370 | D12: CUST10179 | E12: Michael Lopez | F12: Toronto | G12: Canada | H12: Fee | I12: Other | J12: USD | K12: 24.12 | L12: =K12*VLOOKUP(J12,{"USD",1;"EUR",1.08;"GBP",1.27;"JPY",0.0067;"CNY",0.14;"INR",0.012},2,FALSE) -> 24.12 | M12: 188024.67
A13: TXN0000012 | B13: 2025-12-30 | C13: ACC100359 | D13: CUST10175 | E13: Deepa Mueller | F13: Singapore | G13: Singapore | H13: Withdrawal | I13: Dining | J13: USD | K13: 1514.19 | L13: =K13*VLOOKUP(J13,{"USD",1;"EUR",1.08;"GBP",1.27;"JPY",0.0067;"CNY",0.14;"INR",0.012},2,FALSE) -> 1514.19 | M13: 58401.69
... A10001: TXN0010000 | B10001: 2025-03-03 | C10001: ACC100355 | D10001: CUST10174 | E10001: Mary Harris | F10001: Hong Kong | G10001: China | H10001: Payment | I10001: Healthcare | J10001: EUR | K10001: 4739.34 | L10001: =K10001*VLOOKUP(J10001,{"USD",1;"EUR",1.08;"GBP",1.27;"JPY",0.0067;"CNY",0.14;"INR",0.012},2,FALSE) -> 5118.4872 | M10001: 460942.91

Sheet Sheet2
B1: TransactionID | C1: TransactionDate | D1: AccountID | E1: CustomerID | F1: CustomerName | G1: Branch | H1: Country | I1: TransactionType | J1: Category | K1: Currency | L1: Amount | M1: AmountUSD | N1: Balance
B2: TXN00000012 | C2: =C5=VLOOKUP($B$2,Sheet1!$A$2:$M$10001,2,0) -> #N/A | D2: =VLOOKUP($B$2,Sheet1!$A$2:$M$10001,3,0) -> #N/A | E2: =VLOOKUP($B$2,Sheet1!$A$2:$M$10001,4,0) -> #N/A | F2: =VLOOKUP($B$2,Sheet1!$A$2:$M$10001,5,0) -> #N/A | G2: =VLOOKUP($B$2,Sheet1!$A$2:$M$10001,6,0) -> #N/A | H2: =VLOOKUP($B$2,Sheet1!$A$2:$M$10001,7,0) -> #N/A | I2: =VLOOKUP($B$2,Sheet1!$A$2:$M$10001,8,0) -> #N/A | J2: =VLOOKUP($B$2,Sheet1!$A$2:$M$10001,9,0) -> #N/A | K2: =VLOOKUP($B$2,Sheet1!$A$2:$M$10001,10,0) -> #N/A | L2: =VLOOKUP($B$2,Sheet1!$A$2:$M$10001,11,0) -> #N/A | M2: =VLOOKUP($B$2,Sheet1!$A$2:$M$10001,12,0) -> #N/A | N2: =VLOOKUP($B$2,Sheet1!$A$2:$M$10001,13,0) -> #N/A
B8: TXN0000001 | C8: =IFERROR(VLOOKUP($B$8,Sheet1!$A$2:$M$10001,2,0),"not found") -> 2022-08-01

Sheet Sheet3
